Workbook
Name \a: [1]bobudget!#REF!
Name \b: [1]bobudget!#REF!
Name \c: [1]bobudget!#REF!
Name \l: [2]main!#REF!
Name \m: #N/A
Name \q: #N/A
Name ______MAT1: #REF!
Name ______MAT2: #REF!
Name ______MAT3: #REF!
Name ______p24500: #REF!
Name ______ROW2: [1]bobudget!#REF!
Name ______WIP1: #REF!
Name ______WIP2: #REF!
Name _____MAT1: #REF!
Name _____MAT2: #REF!
Name _____MAT3: #REF!
Name _____p24500: #REF!
Name _____ROW2: [1]bobudget!#REF!
Name _____WIP1: #REF!
Name _____WIP2: #REF!
Name ____MAT1: #REF!
Name ____MAT2: #REF!
Name ____MAT3: #REF!
Name ____p24500: #REF!
Name ____ROW2: [1]bobudget!#REF!
Name ____WIP1: #REF!
Name ____WIP2: #REF!
Name ___MAT1: #REF!
Name ___MAT2: #REF!
Name ___MAT3: #REF!
Name ___p24500: #REF!
Name ___ROW2: [3]bobudget!#REF!
Name ___WIP1: #REF!
Name ___WIP2: #REF!
Name __123Graph_A_1: '[4]119'!#REF!
Name __123Graph_A_2: '[5]119'!#REF!
Name __123Graph_A_3: '[5]119'!#REF!
Name __123Graph_A_4: '[4]119'!#REF!
Name __123Graph_B_1: '[4]119'!#REF!
Name __123Graph_B_2: '[5]119'!#REF!
Name __123Graph_B_3: '[5]119'!#REF!
Name __123Graph_B_4: '[4]119'!#REF!
Name __123Graph_C_1: '[4]119'!#REF!
Name __123Graph_C_2: '[5]119'!#REF!
Name __123Graph_C_3: '[5]119'!#REF!
Name __123Graph_C_4: '[4]119'!#REF!
Name __123Graph_X_1: '[4]119'!#REF!
Name __123Graph_X_2: '[5]119'!#REF!
Name __123Graph_X_3: '[5]119'!#REF!
Name __123Graph_X_4: '[4]119'!#REF!
Name __MAT1: #REF!
Name __MAT2: #REF!
Name __MAT3: #REF!
Name __p24500: #REF!
Name __ROW2: [1]bobudget!#REF!
Name __WIP1: #REF!
Name __WIP2: #REF!
Name _1: #REF!
Name _1_1: #REF!
Name _1_2: #REF!

Sheet PQ Audit Checklist
B1: VINFAST PQ/GD&T Gateway audit
G2: LH800 | H2: VF6 | I2: VF6NP
B3: Module | C3: Sub Module | D3: PQ Criteria | E3: Check Item | F3: Evaluation Guide | G3: score | H3: Sore | I3: Score | J3: BM1 Commnet | K3: BM2 Comment | L3: JIRA | M3: BM Row Average | N3: VF6 Row Average | O3: VF6NP Row Average
B4: Exterior | C4: Body | D4: Fit & Finish | E4: Panel gaps, flushness and line alignment | F4: View panel joints from the front, side and an angle. Check uneven gaps, panel height differences and broken styling lines. Measure specified points against DTS. | G4: 6 | H4: 5 | I4: 5 | K4: Carryover design/paint quality | M4: =AVERAGE(G4:G9) -> 6 | N4: =AVERAGE(H4:H9) -> 5.6666667 | O4: =AVERAGE(I4:I9) -> 5.6666667
D5: Aesthetics | E5: Painted surface quality | F5: Check panels in daylight and inspection lighting. Look for dents, waves, paint runs, rough paint texture and dirt trapped in paint. | G5: 6 | H5: 6 | I5: 6 | K5: Balanced / Clean / Calm
D6: Touch & Feel | E6: Surface feel and scratch resistance | F6: Check normal contact areas for rough surfaces and unfinished edges. Inspect paint scratches before and after approved use and cleaning tests. Refer sharp-edge concerns to Safety. | G6: 6 | H6: 5 | I6: 5 | K6: Acceptable / Basic / Lacking refinement
D7: Functionality | E7: Body clearance during use | F7: Open adjacent closures and check loading and cleaning access. Look for rubbing, catching or blocked access. | G7: 6 | H7: 6 | I7: 6 | K7: intuitive / Low friction
D8: Sound Quality | E8: Body creak and rattle | F8: Listen during the approved road test. Record where creaks or rattles occur, the speed and road condition. Confirm the noise source. | G8: 6 | H8: 6 | I8: 6 | K8: Clean / Clear / Moderate richness / Controlled
D9: Harmony & Authenticity | E9: Body design continuity | F9: View the whole vehicle from the front, side and rear. Compare styling lines, panel transitions and intended left/right balance with the approved design. | G9: 6 | H9: 6 | I9: 6 | K9: Harmonized / Genuine-leaning / Mostly coherent
C10: Doors & Closures | D10: Fit & Finish | E10: Closure gaps, flushness and seals | F10: Fully close doors, bonnet and tailgate. Check gaps, panel height differences, corner alignment and seal seating. Recheck after opening and closing. | G10: 5 | H10: 5 | I10: 5 | K10: Carryover door design | M10: =AVERAGE(G10:G15) -> 6 | N10: =AVERAGE(H10:H15) -> 5.5 | O10: =AVERAGE(I10:I15) -> 5.8333333
D11: Aesthetics | E11: Closure surfaces and hardware | F11: Check closures open and closed. Look for dents, paint defects, exposed sealant and poorly finished visible fasteners. | G11: 7 | H11: 6 | I11: 7 | K11: Door handle new design
D12: Touch & Feel | E12: Handle feel and scratch resistance | F12: Grip handles and operate releases. Check comfort, rough edges and looseness. Inspect handles and recesses for scratches after approved use and cleaning tests. | G12: 6 | H12: 5 | I12: 5 | K12: Door handle new design/ poor door closing
D13: Functionality | E13: Opening, closing and latching | F13: Open and close each closure using the specified method. Check smooth movement, operating effort, hold-open function and full latching. | G13: 6 | H13: 6 | I13: 7 | K13: VF6 legacy mud inturusion improved
D14: Sound Quality | E14: Opening and closing sound | F14: Listen while releasing, opening and closing each closure. Check squeaks, metallic ringing, repeated impacts and vibration after closing. | G14: 6 | H14: 5 | I14: 5 | K14: carryover door design/Poor door closing sound
D15: Harmony & Authenticity | E15: Closure feel and finish consistency | F15: Compare handles and visible hardware across the vehicle. Check consistent finishes, operating feel and closing sounds where the same experience is intended. | G15: 6 | H15: 6 | I15: 6 | K15: Harmonized / Genuine-leaning / Mostly coherent
C16: Lighting | D16: Fit & Finish | E16: Lamp installation and alignment | F16: Check lamp-to-body and lamp-to-bumper joints. Look for uneven gaps, incorrect panel height and misaligned internal elements. Compare left and right lamps. | G16: 6 | H16: 5 | I16: 7 | K16: New design. DTS improved | M16: =AVERAGE(G16:G21) -> 6 | N16: =AVERAGE(H16:H21) -> 5.8333333 | O16: =AVERAGE(I16:I21) -> 6.5
D17: Aesthetics | E17: Lens and illuminated appearance | F17: Check lamps off and on in daylight and darkness. Look for lens defects, internal dirt, bright spots, dark areas and unintended colour differences. | G17: 6 | H17: 6 | I17: 7 | K17: New design.
D18: Touch & Feel | E18: Lens finish and scratch resistance | F18: Check accessible lens and trim edges for roughness or looseness. Inspect scratches and haze before and after approved cleaning tests. Review the approved scratch-test results. | G18: 6 | H18: 6 | I18: 6 | K18: solid design. RPS/Datum implemented/No ahrp edge
D19: Functionality | E19: Lighting modes and response | F19: Switch on each applicable lighting mode. Check correct activation, sequence and flicker. Report failures to Lighting Engineering for further assessment. | G19: 6 | H19: 6 | I19: 6 | K19: New design LED/projection lamp
D20: Sound Quality | E20: Lamp operating noise | F20: In a quiet area, operate fitted lamp motors or adjustment functions. Listen for buzzing, chatter or repeated cycling. Mark N/A if no audible mechanism is fitted. | G20: 6 | H20: 6 | I20: 6 | K20: solid design. RPS/Datum implemented
D21: Harmony & Authenticity | E21: Lighting design consistency | F21: View front and rear lighting together with the vehicle design. Check light shapes, intended symmetry and colour against the approved design. | G21: 6 | H21: 6 | I21: 7 | K21: new design improved harmony with surounding part
C22: Glass & Wiper | D22: Fit & Finish | E22: Glass, mouldings and parked wipers | F22: Check glass edges, surrounding mouldings and parked wipers. Look for uneven seating, open corner joints, exposed adhesive and incorrect parking position. | G22: 6 | H22: 5 | I22: 5 | K22: Carryover design/ poor trim fitmenent | M22: =AVERAGE(G22:G27) -> 5.6666667 | N22: =AVERAGE(H22:H27) -> 5.6666667 | O22: =AVERAGE(I22:I27) -> 5.6666667
D23: Aesthetics | E23: Glass clarity and finish | F23: Look through the glass from normal seating positions. Check scratches, haze and distorted views. Inspect the black border and surrounding trim from outside. | G23: 5 | H23: 5 | I23: 5 | K23: Carryover design/ exposed wisher line
D24: Touch & Feel | E24: Contact finish and scratch resistance | F24: Check accessible trim and blade-service areas for rough edges. Inspect glass and trim scratches after approved wiping and cleaning tests. Disable wipers before service-contact checks. | G24: 6 | H24: 6 | I24: 6 | K24: Carryover design
D25: Functionality | E25: Wiping, washing and parking | F25: Wet the glass and operate each wiper mode and washer. Check missed areas, streaks, spray coverage and correct parking. | G25: 5 | H25: 6 | I25: 6 | K25: Carryover design/ unclean area remained
D26: Sound Quality | E26: Wiper noise | F26: Listen while wiping wet glass at each specified speed. Check squeal, blade chatter, motor noise and impacts at reversal or parking. | G26: 6 | H26: 6 | I26: 6 | K26: Carryover design
D27: Harmony & Authenticity | E27: Glass surround integration | F27: View glass mouldings, pillars, cowl and parked wipers together. Check aligned transitions and finishes against the approved design. | G27: 6 | H27: 6 | I27: 6 | K27: Carryover design
C28: Exterior Trim | D28: Fit & Finish | E28: Trim seating and joints | F28: Check grilles, badges, garnish and cladding. Look for uneven gaps, lifted corners and exposed clips. Check attachment using the approved method. | G28: 6 | H28: 5 | I28: 7 | K28: new design improved DTS/RPS/Location strategy | M28: =AVERAGE(G28:G33) -> 6 | N28: =AVERAGE(H28:H33) -> 5.5 | O28: =AVERAGE(I28:I33) -> 6.3333333
D29: Aesthetics | E29: Trim surface finish | F29: Check visible trim for dents, moulding marks, scratches and coating defects. Compare colour, gloss and surface pattern with approved samples. | G29: 6 | H29: 6 | I29: 7 | K29: new design improved DTS
D30: Touch & Feel | E30: Trim feel and scratch resistance | F30: Touch normal contact areas. Check texture, rough edges and looseness. Inspect scratches and scuffs after approved handling and cleaning tests. | G30: 6 | H30: 5 | I30: 6 | K30: Mostly solid/ no sharp edges on A surface
D31: Functionality | E31: Movable trim and access | F31: Operate fitted movable trim. Check smooth movement and access for normal use and cleaning. Mark operating effort N/A for fixed decorative parts. | G31: 6 | H31: 6 | I31: 6 | K31: Reliable
D32: Sound Quality | E32: Trim squeak and rattle | F32: Listen during normal use and the approved road test. Locate trim squeaks or rattles and record the conditions. | G32: 6 | H32: 5 | I32: 6 | K32: solid design. RPS/Datum implemented
D33: Harmony & Authenticity | E33: Trim colour and material harmony | F33: Compare neighbouring painted, plated and textured parts. Check colour, gloss, badge alignment and material appearance against approved samples. | G33: 6 | H33: 6 | I33: 6 | K33: well integrated panel matching with trim
C34: Wheel/Wheel cover /Rim | D34: Fit & Finish | E34: Cover and centre-cap seating | F34: Check wheel covers and centre caps around their edges. Look for uneven seating, open gaps and poor alignment. Check valve access. | G34: 6 | H34: 6 | I34: 6 | K34: new design improved DTS | M34: =AVERAGE(G34:G39) -> 6 | N34: =AVERAGE(H34:H39) -> 6 | O34: =AVERAGE(I34:I39) -> 6.3333333
D35: Aesthetics | E35: Wheel finish | F35: Check wheel faces, recesses and visible fasteners. Look for scratches, paint defects, machining marks and unintended colour differences. | G35: 6 | H35: 6 | I35: 7 | K35: new design improved DTS
D36: Touch & Feel | E36: Edge finish and scratch resistance | F36: Check normal handling areas for rough edges. Inspect scratches after approved cleaning and cover-handling tests. Record tool damage separately. | G36: 6 | H36: 6 | I36: 6 | K36: Mostly solid/ no sharp edges on A surface
D37: Functionality | E37: Valve access and cover operation | F37: Check access for tyre inflation. Remove and refit covers or caps only by the approved procedure. Confirm correct seating and retention. | G37: 6 | H37: 6 | I37: 6 | K37: Reliable
D38: Sound Quality | E38: Cover and cap rattle | F38: Listen during the approved road test. Check cover or cap rattle. Confirm the source is not the tyre, brake or bearing. | G38: 6 | H38: 6 | I38: 6 | K38: solid design. RPS/Datum implemented
D39: Harmony & Authenticity | E39: Wheel design and vehicle match | F39: View the wheels with the complete vehicle. Check wheel design, finish, caps and visible hardware against the approved variant specification. | G39: 6 | H39: 6 | I39: 7 | K39: well integrated wheel design with exterior
B40: Interior | C40: Instrument Panel | D40: Fit & Finish | E40: IP joints and alignment | F40: Sit in the driver and passenger seats. Check joints around doors, displays, vents and trim. Look for uneven gaps and panel height differences. | G40: 7 | H40: 5 | I40: 8 | K40: new design. DTS/RPS/datum imrpoved | M40: =AVERAGE(G40:G45) -> 7 | N40: =AVERAGE(H40:H45) -> 5.5 | O40: =AVERAGE(I40:I45) -> 8
...

Sheet Scoring guide PQ
B1: Subjective Scoring guide line with Kansei lenguage
B2: * Kano category may shift by segment and brand positioning
B3: (e.g., Attractive in LCV, Performance in Premium)
B5: PALS | C5: Kanao | D5: Must/Want | E5: PQ Criteria (Kano) | F5: Innovate (Attractive -> Performance) | G5: Customer Experience | H5: Functionality | I5: Aesthetics | J5: Fit & Finish | K5: Harmony & Authenticity | L5: Sound Quality | M5: Touch & Feel
B6: Uncompetitive | C6: Unacceptable / Below competitive | D6: Must Fix | E6: 1 | F6: Unoriginal / Outdated / Boring | G6: Unacceptable; basic expectations are not met | H6: The assessed task cannot be completed. | I6: The overall appearance is seriously damaged by obvious defects. | J6: Parts are visibly misassembled, displaced or poorly seated. | K6: Parts strongly conflict in design, material or finish. | L6: Severe unwanted noise dominates the experience. | M6: Normal contact is very uncomfortable; surfaces or edges are poorly finished.
E7: 2 | F7: Superficial / Cosmetic / Directionless | G7: Major problems; correction is clearly needed | H7: The task frequently fails or requires repeated attempts. | I7: Several major defects are obvious at first viewing. | J7: Large unintended gaps or steps appear at several visible joints. | K7: Several prominent parts look mismatched or poorly integrated. | L7: Loud rattles, harsh impacts or distortion occur repeatedly. | M7: Rough edges, unstable contact areas or severe texture inconsistency are obvious.
E8: 3 | F8: Generic / Me-too / Forgettable | G8: Clearly below expectations; problems affect normal use | H8: The task works, but repeated awkward actions or high effort are needed. | I8: Obvious defects or uneven finishes reduce the overall appearance. | J8: Uneven gaps, steps or alignment errors are easily noticed. | K8: Colour, material or detail differences make the assembly look disconnected. | L8: Unwanted noise is clearly noticeable during normal operation. | M8: Contact areas feel flimsy, uneven or poorly finished.
E9: 4 | F9: Safe / Conservative / Unexciting | G9: Usable, but noticeable problems reduce perceived quality | H9: The task can be completed, but awkward reach, effort or delays are noticeable. | I9: Visible finish variation or weak detailing makes the product look unrefined. | J9: Visible joint variation reduces the impression of assembly quality. | K9: Some prominent details do not match the surrounding design. | L9: Hollow sounds, squeaks or tonal noise reduce perceived quality. | M9: Local roughness, hard seams or unwanted movement reduce comfort.
B10: Border | C10: Border | D10: Want Fix | E10: 5 | F10: Familiar / Evolutionary / Modest | G10: Acceptable in some areas; improvement is still noticeable | H10: The task works correctly, but some steps or feedback need improvement. | I10: The overall appearance is acceptable, but minor visible details need improvement. | J10: Joints are mostly aligned, with local imperfections noticeable in normal viewing. | K10: The design mostly works together, with a few noticeable mismatches. | L10: Operating sound is acceptable, but occasional unwanted noise or weak feedback remains. | M10: Contact feels acceptable, but texture, support or control feedback lacks consistency.
B11: Competitive | C11: Must-Be | E11: 6 | F11: Practical / Useful / Mildly fresh | G11: Meets expected quality for the intended segment | H11: The task is clear and reliable, with manageable effort and response time. | I11: Surfaces and details look clean and balanced under normal viewing conditions. | J11: Gaps, steps and alignment are controlled; minor imperfections do not distract. | K11: Colours, materials and details work together as intended. | L11: Sound suits the function; unwanted noise does not distract under defined conditions. | M11: Contact areas are comfortable and stable; texture and control feel suit their purpose.
B12: Among leader | C12: Performance | E12: 7 | F12: Meaningful / Value-adding / Modern | G12: Noticeably refined in normal use | H12: The task is smooth and predictable, with clear feedback and low effort. | I12: Finish and detailing show noticeable care and consistency. | J12: Visible joints are precise and consistent across the assembly. | K12: Material transitions and design details are well integrated. | L12: Operating sound is pleasant and controlled across normal use conditions. | M12: Grip, texture, support and control resistance feel refined and consistent.
E13: 8 | F13: Wow / Futuristic / Impressive | G13: Strong execution with few weaknesses | H13: The task is easy to complete across different users and common use conditions. | I13: Surfaces and details remain well executed across different viewing angles. | J13: Joint quality remains consistent across visible areas and operating positions. | K13: Design, materials and interaction create a strongly unified experience. | L13: Sound remains well controlled across modes, speeds or loads relevant to the component. | M13: Frequently touched areas maintain refined feel across positions and repeated use.
B14: Leader | C14: Attractive | E14: 9 | F14: Segment-leading / Emotional / Inspiring | G14: Outstanding execution compared with relevant benchmarks | H14: The task feels natural, with very few unnecessary actions and excellent feedback. | I14: Exceptional detailing creates a distinctive and well-executed appearance. | J14: Assembly precision and finish are consistently outstanding against relevant benchmarks. | K14: Material choices and details clearly express the intended design identity. | L14: Feedback and operating sound are exceptionally well matched to the product. | M14: Contact quality and feedback are exceptionally consistent and satisfying.
E15: 10 | F15: Visionary / Radical / Icon-making | G15: Reference-level execution within the evaluated scope | H15: The task delivers an outstanding experience with no meaningful weakness found in the defined evaluation. | I15: Appearance is exceptionally resolved, with no meaningful weakness found under defined viewing conditions. | J15: Joints and finishes provide reference-level execution throughout the evaluated areas. | K15: Design, materials and interaction are fully coherent throughout the evaluated scope. | L15: Sound provides reference-level execution for the intended function and use conditions. | M15: Contact surfaces and controls provide reference-level comfort, stability and feedback.

Sheet A&U Audit Check list
C1: A&U Gate Check List | H1: BM1 | I1: BM2 | J1: BM3
C2: Module | D2: Sub Module | E2: A&U Criteria | F2: Check Item | G2: Evaluation Guide | H2: score | I2: Sore | J2: Score | K2: BM1 comment | L2: BM2 comment | M2: JIRA | N2: BM Row Average | O2: VF6 Row Average | P2: VF6NP Row Average
C3: Exterior | D3: Doors & Closures — Door / Sliding Door | E3: Accessibility / Reach | F3: Handle reach and entry/exit | G3: Ask target users to reach the handle and enter/exit. Record difficult reach, repeated attempts and assistance needed. | H3: 6 | I3: 5 | J3: 5 | L3: Carryover design/paint quality | N3: =AVERAGE(H3:H9) -> 5.8571429 | O3: =AVERAGE(I3:I9) -> 5.5714286 | P3: =AVERAGE(J3:J9) -> 5.5714286
C4: Exterior | D4: Doors & Closures — Door / Sliding Door | E4: Posture | F4: Entry/exit posture | G4: Observe entry and exit. Record head ducking, body twisting, high leg lifting and contact with surrounding parts. | H4: 5 | I4: 5 | J4: 5 | L4: Carryover design/ No special customer delite features/ balanced
C5: Exterior | D5: Doors & Closures — Door / Sliding Door | E5: Comfort | F5: Door operating effort | G5: Open and close the door using the specified method. Record grip discomfort, excessive effort and difficulty controlling movement. | H5: 6 | I5: 6 | J5: 6 | L5: Balanced / Clean / Calm
C6: Exterior | D6: Doors & Closures — Door / Sliding Door | E6: Space Efficiency | F6: Entry/exit clearance | G6: Repeat entry and exit at the specified door opening and parking clearance. Record restricted movement and head, shoulder, knee or foot contact. | H6: 6 | I6: 5 | J6: 5 | L6: Acceptable / Basic / Lacking refinement
C7: Exterior | D7: Doors & Closures — Door / Sliding Door | E7: Convenience / Usability | F7: Daily door-use scenarios | G7: Complete the specified entry and exit tasks, including carrying items where applicable. Record extra steps, failed tasks and assistance needed. | H7: 6 | I7: 6 | J7: 6 | L7: intuitive / Low friction
C8: Exterior | D8: Doors & Closures — Door / Sliding Door | E8: Intuitiveness | F8: Opening, closing and locking logic | G8: Ask a first-time user to open, close, lock and unlock the door without coaching. Record wrong actions and unclear state feedback. | H8: 6 | I8: 6 | J8: 6 | L8: Clean / Clear / Moderate richness / Controlled
C9: Exterior | D9: Doors & Closures — Door / Sliding Door | E9: Visibility | F9: Handle, opening and step visibility | G9: Check in the specified day and night conditions. Record handles, door edges, steps or nearby obstacles that are difficult to see. | H9: 6 | I9: 6 | J9: 6 | L9: Harmonized / Genuine-leaning / Mostly coherent
C10: Exterior | D10: Doors & Closures — Hood | E10: Accessibility / Reach | F10: Release, latch and service-point reach | G10: Operate the release and secondary latch, then reach the specified maintenance points. Record difficult reach and assistance needed. | H10: 5 | I10: 5 | J10: 5 | L10: Carryover door design | N10: =AVERAGE(H10:H16) -> 6.1428571 | O10: =AVERAGE(I10:I16) -> 5.7142857 | P10: =AVERAGE(J10:J16) -> 6
C11: Exterior | D11: Doors & Closures — Hood | E11: Posture | F11: Hood opening and maintenance posture | G11: Open the hood and perform specified maintenance tasks. Record deep bending, extended reach, twisting and difficult working positions. | H11: 7 | I11: 7 | J11: 7 | L11: New design Door handle semi flush
C12: Exterior | D12: Doors & Closures — Hood | E12: Comfort | F12: Hood effort and movement control | G12: Release, lift, support and close the hood using the prescribed method. Record hand discomfort, excessive effort and difficult movement control. | H12: 7 | I12: 6 | J12: 7 | L12: Door handle new design
C13: Exterior | D13: Doors & Closures — Hood | E13: Space Efficiency | F13: Maintenance hand and tool clearance | G13: Perform specified maintenance tasks with the approved tools or containers. Record hand restriction, tool interference and inaccessible working space. | H13: 6 | I13: 5 | J13: 5 | L13: Door handle new design/ poor door closing
C14: Exterior | D14: Doors & Closures — Hood | E14: Convenience / Usability | F14: Owner-maintenance usability | G14: Follow the owner instructions for specified checks and fluid filling. Record extra steps, difficult access and assistance needed. | H14: 6 | I14: 6 | J14: 7 | L14: VF6 legacy mud inturusion improved
C15: Exterior | D15: Doors & Closures — Hood | E15: Intuitiveness | F15: Release, support and closing sequence | G15: Ask a first-time user to open, support and close the hood using available instructions. Record confusion and unclear latch confirmation. | H15: 6 | I15: 5 | J15: 5 | L15: carryover door design/Poor door closing sound
C16: Exterior | D16: Doors & Closures — Hood | E16: Visibility | F16: Latch, labels and service-point visibility | G16: Check the latch, support position, fluid caps and labels under specified lighting. Record items that are difficult to see or identify. | H16: 6 | I16: 6 | J16: 6 | L16: Harmonized / Genuine-leaning / Mostly coherent
C17: Exterior | D17: Doors & Closures — Tailgate | E17: Accessibility / Reach | F17: Handle, closing control and cargo reach | G17: Ask target users to open and close the tailgate and reach designated cargo locations. Record difficult reach and assistance needed. | H17: 6 | I17: 5 | J17: 7 | L17: New design. DTS improved | N17: =AVERAGE(H17:H23) -> 6 | O17: =AVERAGE(I17:I23) -> 5.8571429 | P17: =AVERAGE(J17:J23) -> 6.4285714
C18: Exterior | D18: Doors & Closures — Tailgate | E18: Posture | F18: Loading and unloading posture | G18: Load and retrieve specified items. Record deep bending, twisting, extended reach and awkward lifting. | H18: 6 | I18: 6 | J18: 6 | L18: No special customer delite features/ balanced
C19: Exterior | D19: Doors & Closures — Tailgate | E19: Comfort | F19: Tailgate effort and movement control | G19: Open and close the tailgate using the specified method. Record grip discomfort, excessive effort and difficulty controlling movement. | H19: 6 | I19: 6 | J19: 7 | L19: New design.
C20: Exterior | D20: Doors & Closures — Tailgate | E20: Space Efficiency | F20: Cargo opening and tailgate clearance | G20: Load specified cargo and check the open tailgate against defined parking and overhead clearances. Record contact, required tilting and restricted access. | H20: 6 | I20: 6 | J20: 6 | L20: solid design. RPS/Datum implemented/No ahrp edge
C21: Exterior | D21: Doors & Closures — Tailgate | E21: Convenience / Usability | F21: Daily cargo-access scenarios | G21: Complete specified shopping, luggage and family-use tasks. Record extra steps, blocked access and difficulty opening or closing with occupied hands. | H21: 6 | I21: 6 | J21: 6 | L21: New design LED/projection lamp
C22: Exterior | D22: Doors & Closures — Tailgate | E22: Intuitiveness | F22: Manual/powered tailgate logic | G22: Ask a first-time user to open, stop and close the fitted tailgate. Record wrong button selections and unclear movement or state feedback. | H22: 6 | I22: 6 | J22: 6 | L22: solid design. RPS/Datum implemented
C23: Exterior | D23: Doors & Closures — Tailgate | E23: Visibility | F23: Tailgate and loading-zone visibility | G23: Check the handle, closing controls, tailgate edge and loading area in day and night conditions. Record difficult-to-see areas. | H23: 6 | I23: 6 | J23: 7 | L23: new design improved harmony with surounding part
C24: Exterior | D24: Charging System — Charging Lid / Port | E24: Accessibility / Reach | F24: Lid, port and connector reach | G24: Use the specified parking position and connector. Reach the lid, port and release controls. Record difficult access and assistance needed. | H24: 6 | I24: 5 | J24: 5 | L24: Carryover design/ poor trim fitmenent | N24: =AVERAGE(H24:H30) -> 5.5714286 | O24: =AVERAGE(I24:I30) -> 5.5714286 | P24: =AVERAGE(J24:J30) -> 5.5714286
C25: Exterior | D25: Charging System — Charging Lid / Port | E25: Posture | F25: Connection and disconnection posture | G25: Connect and disconnect the cable. Record bending, twisting, extended reach and difficulty maintaining the working position. | H25: 5 | I25: 5 | J25: 5 | L25: Carryover design
C26: Exterior | D26: Charging System — Charging Lid / Port | E26: Comfort | F26: Connector and cable handling | G26: Handle the specified connector and cable. Record grip discomfort, insertion/removal effort and difficulty supporting the cable. | H26: 5 | I26: 5 | J26: 5 | L26: Carryover design/ exposed wisher line
C27: Exterior | D27: Charging System — Charging Lid / Port | E27: Space Efficiency | F27: Hand and cable clearance | G27: Connect the cable in the specified parking space. Record hand restriction, lid interference and cable-routing conflicts. | H27: 6 | I27: 6 | J27: 6 | L27: Carryover design
C28: Exterior | D28: Charging System — Charging Lid / Port | E28: Convenience / Usability | F28: Daily charging scenarios | G28: Complete approved home and public-charging scenarios under specified lighting and weather conditions. Record failed steps, repeated attempts and assistance needed. | H28: 5 | I28: 6 | J28: 6 | L28: Carryover design/ unclean area remained
C29: Exterior | D29: Charging System — Charging Lid / Port | E29: Intuitiveness | F29: Charging sequence and status | G29: Ask a first-time user to start and stop charging without coaching. Record wrong actions and uncertainty about connection, charging or release status. | H29: 6 | I29: 6 | J29: 6 | L29: Carryover design
C30: Exterior | D30: Charging System — Charging Lid / Port | E30: Visibility | F30: Port orientation and status visibility | G30: Check the port, connector orientation and status indicators in daylight and darkness. Record information that is difficult to see or distinguish. | H30: 6 | I30: 6 | J30: 6 | L30: Carryover design
C31: Exterior | D31: Exterior Trim — Side Step | E31: Accessibility / Reach | F31: Step-assisted entry/exit | G31: Ask target users to enter and exit using the step. Record difficulty reaching the step or supporting handhold and assistance needed. | H31: 6 | I31: 5 | J31: 7 | L31: new design improved DTS/RPS/Location strategy | N31: =AVERAGE(H31:H37) -> 6 | O31: =AVERAGE(I31:I37) -> 5.5714286 | P31: =AVERAGE(J31:J37) -> 6.2857143
C32: Exterior | D32: Exterior Trim — Side Step | E32: Posture | F32: Step-assisted body movement | G32: Observe step use during entry and exit. Record excessive leg lifting, twisting, awkward foot placement and body contact. | H32: 6 | I32: 6 | J32: 6 | L32: No special customer delite features/ balanced
C33: Exterior | D33: Exterior Trim — Side Step | E33: Comfort | F33: Foot support and confidence | G33: Use approved footwear and surface conditions. Record pressure discomfort, unstable footing and perceived slipping. Refer slip concerns for specialist assessment. | H33: 6 | I33: 6 | J33: 7 | L33: new design improved DTS
C34: Exterior | D34: Exterior Trim — Side Step | E34: Space Efficiency | F34: Usable foothold and clearance | G34: Check foot placement and body clearance for target users. Record insufficient foothold, door interference and restriction of the entry path. | H34: 6 | I34: 5 | J34: 6 | L34: Mostly solid/ no sharp edges on A surface
C35: Exterior | D35: Exterior Trim — Side Step | E35: Convenience / Usability | F35: Daily access assistance | G35: Complete specified entry/exit tasks with carried items where applicable. Record whether the step helps access or creates extra movements and clothing contact. | H35: 6 | I35: 6 | J35: 6 | L35: Reliable
C36: Exterior | D36: Exterior Trim — Side Step | E36: Intuitiveness | F36: Step-use recognition | G36: Ask a first-time user to enter without coaching. Record uncertainty about where to step or where to hold. | H36: 6 | I36: 5 | J36: 6 | L36: solid design. RPS/Datum implemented
C37: Exterior | D37: Exterior Trim — Side Step | E37: Visibility | F37: Step surface and edge visibility | G37: Check from approach and exit positions in day and night conditions. Record step surfaces or edges that are difficult to see. | H37: 6 | I37: 6 | J37: 6 | L37: well integrated panel matching with trim
C38: Exterior | D38: Mirror System — ORVM | E38: Accessibility / Reach | F38: Mirror-control reach | G38: From the specified driving position, operate mirror controls. Record difficult reach and the need to leave the normal seated position. | H38: 6 | I38: 6 | J38: 6 | L38: new design improved DTS | N38: =AVERAGE(H38:H44) -> 6 | O38: =AVERAGE(I38:I44) -> 6 | P38: =AVERAGE(J38:J44) -> 6.2857143
C39: Exterior | D39: Mirror System — ORVM | E39: Posture | F39: Mirror-viewing posture | G39: Adjust mirrors and view specified targets. Record excessive head movement, neck rotation and body leaning. | H39: 6 | I39: 6 | J39: 6 | L39: No special customer delite features/ balanced
C40: Exterior | D40: Mirror System — ORVM | E40: Comfort | F40: Mirror-view comfort | G40: View specified targets under approved conditions. Record eye strain, distracting reflections, image vibration and perceived distortion. | H40: 6 | I40: 6 | J40: 7 | L40: new design improved DTS
...

Sheet Scoring guide A&U
D3: PALS | E3: Kano | F3: Must / Want | G3: Score | H3: Accessibility | I3: Posture | J3: Comfort | K3: Space Efficiency | L3: Convenience & Usability | M3: Intuitiveness | N3: Visibility
D4: Uncompetitive | E4: Unacceptable / Below competitive | F4: Must Fix | G4: 1 | H4: The required feature cannot be reached or accessed by the target user. | I4: The task cannot be completed in a usable posture. | J4: Pain or severe discomfort prevents continued use. | K4: The target occupant or required item cannot be accommodated. | L4: The required task cannot be completed. | M4: The user cannot understand how to complete the task without assistance. | N4: The required object or information cannot be seen from the intended position.
G5: 2 | H5: Access requires assistance or a major change of body position. | I5: Deep bending, strong twisting or extended reach is repeatedly required. | J5: Strong pressure or fatigue requires the user to stop or change position frequently. | K5: Severe space restrictions prevent normal movement or item handling. | L5: The task frequently fails or requires assistance and repeated attempts. | M5: The user repeatedly selects the wrong action and needs substantial guidance. | N5: Major obstruction, glare or poor lighting makes the required target very difficult to see.
G6: 3 | H6: Access requires noticeable stretching, leaning or several attempts. | I6: The task requires an awkward posture that is difficult to maintain. | J6: Clear discomfort develops during the specified use period. | K6: Several contact or interference points restrict normal use. | L6: The task is completed with repeated extra steps, errors or workarounds. | M6: The user completes the task only after repeated trial and error. | N6: The user must repeatedly reposition or search to see the required target.
G7: 4 | H7: Access is possible, but noticeable reach effort or repositioning remains. | I7: Some bending, twisting or loss of support is needed during normal use. | J7: Local pressure or discomfort reduces the quality of normal use. | K7: Local clearance restrictions require repositioning of the body or items. | L7: The task works, but awkward steps or occasional retries are needed. | M7: The user hesitates or makes an incorrect selection before understanding the task. | N7: Some required targets are difficult to see because of obstruction, glare or low contrast.
D8: Border | E8: Border | F8: Want Fix | G8: 5 | H8: Access is acceptable, with minor stretching or repositioning. | I8: The posture is acceptable, but local awkwardness remains. | J8: Comfort is acceptable, but mild discomfort remains over the specified duration. | K8: Occupants and items fit, but usable clearance or retrieval space is limited. | L8: The task is completed reliably, but avoidable steps or inconvenience remain. | M8: The user understands the task after brief searching or a minor correction. | N8: The target can be seen, but some viewing effort or adjustment is needed.
D9: Competitive | E9: Must-Be | G9: 6 | H9: Required features are reached using normal movement for the task. | I9: The task is completed in a natural posture with adequate support. | J9: Comfort meets the approved target over the specified use duration. | K9: Target occupants and items fit with sufficient clearance for normal use. | L9: The task is completed reliably with clear steps and manageable effort. | M9: The user completes the task with little hesitation and clear feedback. | N9: Required targets are clearly visible under the defined evaluation conditions.
D10: Among Leader | E10: Performance | G10: 7 | H10: Access is easy and repeatable, with little need to reposition. | I10: The posture remains natural and supported throughout the task. | J10: Support and contact feel remain comfortable during repeated use. | K10: Space supports easy movement, placement and retrieval of specified items. | L10: The task is smooth and predictable, with few unnecessary actions. | M10: The user quickly identifies the correct action and understands the result. | N10: Targets are easy to identify, with well-controlled glare and obstruction.
G11: 8 | H11: Access remains easy across the defined users and common use scenarios. | I11: Good posture is maintained across the defined users and adjustment positions. | J11: Comfort remains consistent across the defined users and intended conditions. | K11: Space supports the specified uses together with little interference. | L11: The task remains easy across common scenarios, with clear recovery from errors. | M11: Related tasks use consistent logic and require little learning. | N11: Visibility remains clear across the specified positions and lighting conditions.
D12: Leader | E12: Attractive | G12: 9 | H12: Access is exceptionally well resolved against relevant benchmarks. | I12: Posture and support are exceptionally well resolved against relevant benchmarks. | J12: Comfort and support are outstanding over the intended use duration. | K12: Available space is exceptionally usable without compromising neighbouring functions. | L12: The complete use sequence is exceptionally convenient against relevant benchmarks. | M12: First-time use is exceptionally clear, including status and error recovery. | N12: Required targets are exceptionally easy to identify against relevant benchmarks.
G13: 10 | H13: Reference-level access is demonstrated throughout the evaluated scope. | I13: Reference-level posture and support are demonstrated throughout the evaluated scope. | J13: Reference-level comfort is demonstrated for the defined users and duration. | K13: Reference-level space utilization is demonstrated for the specified occupants and tasks. | L13: Reference-level task flow is demonstrated with no meaningful usability weakness found. | M13: Reference-level first-use understanding is demonstrated throughout the evaluated tasks. | N13: Reference-level visibility is demonstrated throughout the defined evaluation conditions.

Sheet Must_Want Fix Guide
B2: ⏹ Issue clarifications (Safety/Functionality/Appearance)
B4: Group | C4: Effect | D4: VF DFMEA Severity | E4: VF JIRA Severity | F4: VCA Mapping | G4: Classification | H4: Customer Effect Criteria | I4: Assessment Checkpoints | J4: Lead Assessment Group / PIC | K4: Supporting Assessment Groups | L4: Must Fix / Want Fix | M4: Deviation Eligibility | N4: Example
B5: Safety / Regulatory | C5: Failure to Meet Safety and/or Regulatory Requirements | D5: 10 | E5: PS / PL | F5: 50 | G5: <CC> Critical Characteristics | H5: Affects safe vehicle operation and/or regulatory compliance without warning | I5: Safety hazard; applicable legal requirement; warning availability and effectiveness | J5: Safety / FuSa / VPAC; Homologation / Compliance for regulatory issues | K5: Relevant System / Component Engineering; EE / Software; Validation / DVP; VCA / Quality; Manufacturing / Supplier Quality; After-sales | L5: Must Fix | M5: Not permitted — correction and verification required | N5: 1. Brakes fail without warning, preventing safe stopping. 2. Steering control is lost without warning. 3. An electrical fault causes a fire without warning.
D6: 9 | H6: Affects safe vehicle operation and/or regulatory compliance with warning | L6: Must Fix | M6: Not permitted — correction and verification required | N6: 1. Brakes fail despite a warning, preventing safe stopping. 2. Steering control is lost despite a warning. 3. An electrical fault causes a fire despite a warning.
B7: Functional | C7: Loss or Degradation of Primary Function | D7: 8 | E7: W | F7: 50 | G7: <SC> Significant Characteristics | H7: Loss of primary function; vehicle inoperable, without affecting safe operation | I7: Vehicle operability; failed driving function; performance against approved requirements | J7: Relevant Function Engineering Team + VCA | K7: Vehicle Architecture; EE / Software / Controls; Validation / Reliability; Manufacturing / QE / QC; Supplier Quality; After-sales; relevant attribute teams | L7: Must Fix | M7: Not permitted — correction and verification required | N7: 1. The parked vehicle cannot enter Ready mode. 2. Drive cannot be selected while parked. 3. The parked vehicle has no drive power.
D8: 7 | H8: Degradation of primary function; vehicle operable with reduced performance | L8: Must Fix | M8: Not permitted — correction and verification required | N8: 1. Drive power is below the required level. 2. Acceleration is below the required performance. 3. Vehicle speed is unexpectedly limited below the required level.
C9: Loss or Degradation of Secondary Function | D9: 6 | E9: A | F9: 40 | G9: <HIC> High Importance Characteristics | H9: Loss of secondary function; vehicle operable, but comfort/convenience function inoperable | I9: Function availability; operating performance; required user effort; daily-use inconvenience | J9: Relevant Function Engineering Team + VCA; A&U for usability and ergonomics | K9: EE / Software / UX; Vehicle Architecture; Validation / Reliability; PQ / GD&T where applicable; Manufacturing / QE / QC; Supplier Quality; After-sales | L9: Must Fix | M9: Not permitted — correction and verification required | N9: 1. The seat heater does not work. 2. The audio system produces no sound. 3. The seat massage function does not work.
D10: 5 | H10: Degradation of secondary function; reduced comfort/convenience performance | L10: Must Fix | M10: Not permitted — correction and verification required | N10: 1. The seat heater takes longer than the required warm-up time. 2. The audio system repeatedly cuts out. 3. Seat massage strength is below the required level.
B11: Appearance / Sound / Perceived Quality | C11: Customer Perception/ Annoyance | D11: 4 | E11: B | F11: 20 | G11: <STD> Standard Characteristics | H11: Appearance or audible-noise nonconformity noticed by most customers >75% | I11: Visibility / audibility under defined conditions; gap / flush consistency; surface defects; colour / grain / gloss harmony; customer acceptance | J11: Relevant Attribute Owner + VCA: PQ / GD&T / A&U / Sound–NVH, according to the issue | K11: Styling / CMF; Body / Interior / Exterior Engineering; EE / UX where applicable; Materials / Paint; Validation / Reliability; Manufacturing / QE / QC; Supplier Quality; After-sales | L11: Must Fix | M11: Not permitted — correction and verification required | N11: 1. Easily visible permanent trim scratches/Sink /gate /paint defects 2. Excessive wind noise fails the highway-driving acceptance criteria. 3. Uneven panel gaps fail the appearance acceptance criteria.
D12: 3 | E12: C | F12: 5 | H12: Appearance or audible-noise nonconformity noticed by many customers >50% | L12: Want Fix | M12: May be approved based on condition | N12: 1. A small trim colour difference is noticeable but acceptable. 2. A minor panel alignment difference is noticeable but acceptable. 3. A slightly hollow switch sound is noticeable but acceptable.
D13: 2 | H13: Appearance or audible-noise nonconformity noticed by discriminating customers >25%, per internal source | L13: Want Fix | M13: May be approved based on condition | N13: 1. A minor trim gloss difference is acceptable. 2. A slight grain difference between trim parts is acceptable. 3. A faint trim squeak under specific conditions is acceptable.
C14: No effect | D14: 1 | E14: No issue / lowest classification | F14: 1 | H14: No discernible effect | I14: Confirm no customer effect and check mandatory requirement | J14: Relevant Attribute / Function Owner | K14: VCA / Quality and other affected groups, as required | L14: No Fix Required | M14: Generally not required | N14: 1. A hidden trim surface has a cosmetic mark with no other effect. 2. A hidden moulding mark has no customer or performance effect. 3. A hidden colour difference has no customer or performance effect.
B16: ⏹ Must fix Permanent Deviation Proposal Eligibility
B17: Permanent Deviation may be proposed by the responsible Engineering organization when one or more of the following conditions exist:
B18: 1. Engineering or technical limitations prevent full compliance within the program timeline.
B19: 2. Manufacturing or process limitations prevent achievement of the target requirement.
B20: 3. The cost required for correction is disproportionate to the customer benefit or business impact.
B21: 4. The implementation timing required for correction is not compatible with the approved program milestone or SOP timing.
B22: 5. Customer impact is assessed as low and acceptable based on cross-functional evaluation.
B23: ⏹ Must fix Permanent Deviation Approval Rules
B24: Permanent Deviation may only be considered when all conditions below are satisfied:
B25: 1. No Safety impact.
B26: 2. No Regulatory / Homologation impact.
B27: 3. No Primary Function impact.
... B32: 8. Approval by the responsible quality authority is obtained.

Sheet Sheet11

Sheet PQ Criteria
B1: PQ Criteria | C1: BYD | D1: VF6 | E1: VF6NP | F1: Competitive Position | G1: Assessment
B2: Functionality | C2: =AVERAGE('PQ Audit Checklist'!G7,'PQ Audit Checklist'!G13,'PQ Audit Checklist'!G19,'PQ Audit Checklist'!G25,'PQ Audit Checklist'!G31,'PQ Audit Checklist'!G37,'PQ Audit Checklist'!G43,'PQ Audit Checklist'!G49,'PQ Audit Checklist'!G55,'PQ Audit Checklist'!G61,'PQ Audit Checklist'!G67,'PQ Audit Checklist'!G73:G79,'PQ Audit Checklist'!G73,'PQ Audit Checklist'!G85,'PQ Audit Checklist'!G97) -> 6.7142857 | D2: =AVERAGE('PQ Audit Checklist'!H7,'PQ Audit Checklist'!H13,'PQ Audit Checklist'!H19,'PQ Audit Checklist'!H25,'PQ Audit Checklist'!H31,'PQ Audit Checklist'!H37,'PQ Audit Checklist'!H43,'PQ Audit Checklist'!H49,'PQ Audit Checklist'!H55,'PQ Audit Checklist'!H61,'PQ Audit Checklist'!H67,'PQ Audit Checklist'!H73:H79,'PQ Audit Checklist'!H73,'PQ Audit Checklist'!H85,'PQ Audit Checklist'!H97) -> 5.7142857 | E2: =AVERAGE('PQ Audit Checklist'!I7,'PQ Audit Checklist'!I13,'PQ Audit Checklist'!I19,'PQ Audit Checklist'!I25,'PQ Audit Checklist'!I31,'PQ Audit Checklist'!I37,'PQ Audit Checklist'!I43,'PQ Audit Checklist'!I49,'PQ Audit Checklist'!I55,'PQ Audit Checklist'!I61,'PQ Audit Checklist'!I67,'PQ Audit Checklist'!I73:I79,'PQ Audit Checklist'!I73,'PQ Audit Checklist'!I85,'PQ Audit Checklist'!I97) -> 6.9047619 | F2: VF6NP Leading | G2: Clear improvement, strong usability execution
B3: Aesthetics | C3: =AVERAGEA('PQ Audit Checklist'!G5,'PQ Audit Checklist'!G11,'PQ Audit Checklist'!G17,'PQ Audit Checklist'!G23,'PQ Audit Checklist'!G29,'PQ Audit Checklist'!G35,'PQ Audit Checklist'!G41,'PQ Audit Checklist'!G47,'PQ Audit Checklist'!G53,'PQ Audit Checklist'!G59,'PQ Audit Checklist'!G65,'PQ Audit Checklist'!G71,'PQ Audit Checklist'!G77,'PQ Audit Checklist'!G83,'PQ Audit Checklist'!G95) -> 6.6666667 | D3: =AVERAGEA('PQ Audit Checklist'!H5,'PQ Audit Checklist'!H11,'PQ Audit Checklist'!H17,'PQ Audit Checklist'!H23,'PQ Audit Checklist'!H29,'PQ Audit Checklist'!H35,'PQ Audit Checklist'!H41,'PQ Audit Checklist'!H47,'PQ Audit Checklist'!H53,'PQ Audit Checklist'!H59,'PQ Audit Checklist'!H65,'PQ Audit Checklist'!H71,'PQ Audit Checklist'!H77,'PQ Audit Checklist'!H83,'PQ Audit Checklist'!H95) -> 5.9333333 | E3: =AVERAGEA('PQ Audit Checklist'!I5,'PQ Audit Checklist'!I11,'PQ Audit Checklist'!I17,'PQ Audit Checklist'!I23,'PQ Audit Checklist'!I29,'PQ Audit Checklist'!I35,'PQ Audit Checklist'!I41,'PQ Audit Checklist'!I47,'PQ Audit Checklist'!I53,'PQ Audit Checklist'!I59,'PQ Audit Checklist'!I65,'PQ Audit Checklist'!I71,'PQ Audit Checklist'!I77,'PQ Audit Checklist'!I83,'PQ Audit Checklist'!I95) -> 7 | F3: VF6NP Leading | G3: Strong design quality and premium perception
B4: Fit & Finish | C4: =AVERAGE('PQ Audit Checklist'!G4,'PQ Audit Checklist'!G10,'PQ Audit Checklist'!G16,'PQ Audit Checklist'!G22,'PQ Audit Checklist'!G28,'PQ Audit Checklist'!G34,'PQ Audit Checklist'!G40,'PQ Audit Checklist'!G46,'PQ Audit Checklist'!G52,'PQ Audit Checklist'!G58,'PQ Audit Checklist'!G64,'PQ Audit Checklist'!G70,'PQ Audit Checklist'!G76,'PQ Audit Checklist'!G82,'PQ Audit Checklist'!G94) -> 6.6 | D4: =AVERAGE('PQ Audit Checklist'!H4,'PQ Audit Checklist'!H10,'PQ Audit Checklist'!H16,'PQ Audit Checklist'!H22,'PQ Audit Checklist'!H28,'PQ Audit Checklist'!H34,'PQ Audit Checklist'!H40,'PQ Audit Checklist'!H46,'PQ Audit Checklist'!H52,'PQ Audit Checklist'!H58,'PQ Audit Checklist'!H64,'PQ Audit Checklist'!H70,'PQ Audit Checklist'!H76,'PQ Audit Checklist'!H82,'PQ Audit Checklist'!H94) -> 5.5333333 | E4: =AVERAGE('PQ Audit Checklist'!I4,'PQ Audit Checklist'!I10,'PQ Audit Checklist'!I16,'PQ Audit Checklist'!I22,'PQ Audit Checklist'!I28,'PQ Audit Checklist'!I34,'PQ Audit Checklist'!I40,'PQ Audit Checklist'!I46,'PQ Audit Checklist'!I52,'PQ Audit Checklist'!I58,'PQ Audit Checklist'!I64,'PQ Audit Checklist'!I70,'PQ Audit Checklist'!I76,'PQ Audit Checklist'!I82,'PQ Audit Checklist'!I94) -> 7.1333333 | F4: VF6NP Strong Leader | G4: Best-in-class execution, major gap closure
B5: Touch & Feel | C5: =AVERAGE('PQ Audit Checklist'!G6,'PQ Audit Checklist'!G12,'PQ Audit Checklist'!G18,'PQ Audit Checklist'!G24,'PQ Audit Checklist'!G30,'PQ Audit Checklist'!G36,'PQ Audit Checklist'!G42,'PQ Audit Checklist'!G48,'PQ Audit Checklist'!G54,'PQ Audit Checklist'!G60,'PQ Audit Checklist'!G66,'PQ Audit Checklist'!G72,'PQ Audit Checklist'!G78,'PQ Audit Checklist'!G84,'PQ Audit Checklist'!G96) -> 6.6666667 | D5: =AVERAGE('PQ Audit Checklist'!H6,'PQ Audit Checklist'!H12,'PQ Audit Checklist'!H18,'PQ Audit Checklist'!H24,'PQ Audit Checklist'!H30,'PQ Audit Checklist'!H36,'PQ Audit Checklist'!H42,'PQ Audit Checklist'!H48,'PQ Audit Checklist'!H54,'PQ Audit Checklist'!H60,'PQ Audit Checklist'!H66,'PQ Audit Checklist'!H72,'PQ Audit Checklist'!H78,'PQ Audit Checklist'!H84,'PQ Audit Checklist'!H96) -> 5.8 | E5: =AVERAGE('PQ Audit Checklist'!I6,'PQ Audit Checklist'!I12,'PQ Audit Checklist'!I18,'PQ Audit Checklist'!I24,'PQ Audit Checklist'!I30,'PQ Audit Checklist'!I36,'PQ Audit Checklist'!I42,'PQ Audit Checklist'!I48,'PQ Audit Checklist'!I54,'PQ Audit Checklist'!I60,'PQ Audit Checklist'!I66,'PQ Audit Checklist'!I72,'PQ Audit Checklist'!I78,'PQ Audit Checklist'!I84,'PQ Audit Checklist'!I96) -> 6.3333333 | F5: BYD Leading | G5: Noticeable gap in tactile density and refinement
B6: Sound Quality | C6: =AVERAGE('PQ Audit Checklist'!G8,'PQ Audit Checklist'!G14,'PQ Audit Checklist'!G20,'PQ Audit Checklist'!G26,'PQ Audit Checklist'!G32,'PQ Audit Checklist'!G38,'PQ Audit Checklist'!G44,'PQ Audit Checklist'!G50,'PQ Audit Checklist'!G56,'PQ Audit Checklist'!G62,'PQ Audit Checklist'!G68,'PQ Audit Checklist'!G74,'PQ Audit Checklist'!G80,'PQ Audit Checklist'!G86,'PQ Audit Checklist'!G98) -> 6.1333333 | D6: =AVERAGE('PQ Audit Checklist'!H8,'PQ Audit Checklist'!H14,'PQ Audit Checklist'!H20,'PQ Audit Checklist'!H26,'PQ Audit Checklist'!H32,'PQ Audit Checklist'!H38,'PQ Audit Checklist'!H44,'PQ Audit Checklist'!H50,'PQ Audit Checklist'!H56,'PQ Audit Checklist'!H62,'PQ Audit Checklist'!H68,'PQ Audit Checklist'!H74,'PQ Audit Checklist'!H80,'PQ Audit Checklist'!H86,'PQ Audit Checklist'!H98) -> 5.7333333 | E6: =AVERAGE('PQ Audit Checklist'!I8,'PQ Audit Checklist'!I14,'PQ Audit Checklist'!I20,'PQ Audit Checklist'!I26,'PQ Audit Checklist'!I32,'PQ Audit Checklist'!I38,'PQ Audit Checklist'!I44,'PQ Audit Checklist'!I50,'PQ Audit Checklist'!I56,'PQ Audit Checklist'!I62,'PQ Audit Checklist'!I68,'PQ Audit Checklist'!I74,'PQ Audit Checklist'!I80,'PQ Audit Checklist'!I86,'PQ Audit Checklist'!I98) -> 6.1333333 | F6: BYD = VF6NP | G6: Acceptable but no differentiation
B7: Harmony & Authenticity | C7: =AVERAGE('PQ Audit Checklist'!G9,'PQ Audit Checklist'!G15,'PQ Audit Checklist'!G21,'PQ Audit Checklist'!G27,'PQ Audit Checklist'!G33,'PQ Audit Checklist'!G39,'PQ Audit Checklist'!G45,'PQ Audit Checklist'!G51,'PQ Audit Checklist'!G57,'PQ Audit Checklist'!G63,'PQ Audit Checklist'!G69,'PQ Audit Checklist'!G75,'PQ Audit Checklist'!G81,'PQ Audit Checklist'!G87,'PQ Audit Checklist'!G99) -> 6.7333333 | D7: =AVERAGE('PQ Audit Checklist'!H9,'PQ Audit Checklist'!H15,'PQ Audit Checklist'!H21,'PQ Audit Checklist'!H27,'PQ Audit Checklist'!H33,'PQ Audit Checklist'!H39,'PQ Audit Checklist'!H45,'PQ Audit Checklist'!H51,'PQ Audit Checklist'!H57,'PQ Audit Checklist'!H63,'PQ Audit Checklist'!H69,'PQ Audit Checklist'!H75,'PQ Audit Checklist'!H81,'PQ Audit Checklist'!H87,'PQ Audit Checklist'!H99) -> 6 | E7: =AVERAGE('PQ Audit Checklist'!I9,'PQ Audit Checklist'!I15,'PQ Audit Checklist'!I21,'PQ Audit Checklist'!I27,'PQ Audit Checklist'!I33,'PQ Audit Checklist'!I39,'PQ Audit Checklist'!I45,'PQ Audit Checklist'!I51,'PQ Audit Checklist'!I57,'PQ Audit Checklist'!I63,'PQ Audit Checklist'!I69,'PQ Audit Checklist'!I75,'PQ Audit Checklist'!I81,'PQ Audit Checklist'!I87,'PQ Audit Checklist'!I99) -> 6.9333333 | F7: VF6NP Leading | G7: Strong improvement in brand consistency
B8: Average | C8: =AVERAGE(C2:C7) -> 6.5857143 | D8: =AVERAGE(D2:D7) -> 5.7857143 | E8: =AVERAGE(E2:E7) -> 6.7396825 | F8: VF6NP Leading | G8: Overall competitive position achieved
B11: Exterior | C11: BYD | D11: VF6 | E11: VF6NP | F11: Competitive Position | G11: Assessment
B12: Functionality | C12: =AVERAGE('PQ Audit Checklist'!G7,'PQ Audit Checklist'!G13,'PQ Audit Checklist'!G19,'PQ Audit Checklist'!G25,'PQ Audit Checklist'!G31,'PQ Audit Checklist'!G37) -> 5.8333333 | D12: =AVERAGE('PQ Audit Checklist'!H7,'PQ Audit Checklist'!H13,'PQ Audit Checklist'!H19,'PQ Audit Checklist'!H25,'PQ Audit Checklist'!H31,'PQ Audit Checklist'!H37) -> 6 | E12: =AVERAGE('PQ Audit Checklist'!I7,'PQ Audit Checklist'!I13,'PQ Audit Checklist'!I19,'PQ Audit Checklist'!I25,'PQ Audit Checklist'!I31,'PQ Audit Checklist'!I37) -> 6.1666667 | F12: VF6NP Leading | G12: Clear improvement in usability and functional execution
B13: Aesthetics | C13: =AVERAGE('PQ Audit Checklist'!G5,'PQ Audit Checklist'!G11,'PQ Audit Checklist'!G17,'PQ Audit Checklist'!G23,'PQ Audit Checklist'!G29,'PQ Audit Checklist'!G35) -> 6 | D13: =AVERAGE('PQ Audit Checklist'!H5,'PQ Audit Checklist'!H11,'PQ Audit Checklist'!H17,'PQ Audit Checklist'!H23,'PQ Audit Checklist'!H29,'PQ Audit Checklist'!H35) -> 5.8333333 | E13: =AVERAGE('PQ Audit Checklist'!I5,'PQ Audit Checklist'!I11,'PQ Audit Checklist'!I17,'PQ Audit Checklist'!I23,'PQ Audit Checklist'!I29,'PQ Audit Checklist'!I35) -> 6.5 | F13: VF6NP Leading | G13: Strong design refinement
B14: Fit & Finish | C14: =AVERAGE('PQ Audit Checklist'!G10,'PQ Audit Checklist'!G16,'PQ Audit Checklist'!G22,'PQ Audit Checklist'!G28,'PQ Audit Checklist'!G34,'PQ Audit Checklist'!G4) -> 5.8333333 | D14: =AVERAGE('PQ Audit Checklist'!H10,'PQ Audit Checklist'!H16,'PQ Audit Checklist'!H22,'PQ Audit Checklist'!H28,'PQ Audit Checklist'!H34,'PQ Audit Checklist'!H4) -> 5.1666667 | E14: =AVERAGE('PQ Audit Checklist'!I10,'PQ Audit Checklist'!I16,'PQ Audit Checklist'!I22,'PQ Audit Checklist'!I28,'PQ Audit Checklist'!I34,'PQ Audit Checklist'!I4) -> 5.8333333 | F14: BYD = VF6NP | G14: Meet CN OEM level of gap & flush target
B15: Touch & Feel | C15: =AVERAGE('PQ Audit Checklist'!G6,'PQ Audit Checklist'!G12,'PQ Audit Checklist'!G18,'PQ Audit Checklist'!G24,'PQ Audit Checklist'!G30,'PQ Audit Checklist'!G36) -> 6 | D15: =AVERAGE('PQ Audit Checklist'!H6,'PQ Audit Checklist'!H12,'PQ Audit Checklist'!H18,'PQ Audit Checklist'!H24,'PQ Audit Checklist'!H30,'PQ Audit Checklist'!H36) -> 5.5 | E15: =AVERAGE('PQ Audit Checklist'!I6,'PQ Audit Checklist'!I12,'PQ Audit Checklist'!I18,'PQ Audit Checklist'!I24,'PQ Audit Checklist'!I30,'PQ Audit Checklist'!I36) -> 5.6666667 | F15: BYD Leading | G15: Tactile quality still weaker vs benchmark ( Door closing)
B16: Sound Quality | C16: =AVERAGE('PQ Audit Checklist'!G8,'PQ Audit Checklist'!G14,'PQ Audit Checklist'!G20,'PQ Audit Checklist'!G26,'PQ Audit Checklist'!G32,'PQ Audit Checklist'!G38) -> 6 | D16: =AVERAGE('PQ Audit Checklist'!H8,'PQ Audit Checklist'!H14,'PQ Audit Checklist'!H20,'PQ Audit Checklist'!H26,'PQ Audit Checklist'!H32,'PQ Audit Checklist'!H38) -> 5.6666667 | E16: =AVERAGE('PQ Audit Checklist'!I8,'PQ Audit Checklist'!I14,'PQ Audit Checklist'!I20,'PQ Audit Checklist'!I26,'PQ Audit Checklist'!I32,'PQ Audit Checklist'!I38) -> 5.8333333 | F16: BYD Leading | G16: Acoustic feedback not yet competitive (Door closing)
B17: Harmony & Authenticity | C17: =AVERAGE('PQ Audit Checklist'!G9,'PQ Audit Checklist'!G15,'PQ Audit Checklist'!G21,'PQ Audit Checklist'!G27,'PQ Audit Checklist'!G33,'PQ Audit Checklist'!G39) -> 6 | D17: =AVERAGE('PQ Audit Checklist'!H9,'PQ Audit Checklist'!H15,'PQ Audit Checklist'!H21,'PQ Audit Checklist'!H27,'PQ Audit Checklist'!H33,'PQ Audit Checklist'!H39) -> 6 | E17: =AVERAGE('PQ Audit Checklist'!I9,'PQ Audit Checklist'!I15,'PQ Audit Checklist'!I21,'PQ Audit Checklist'!I27,'PQ Audit Checklist'!I33,'PQ Audit Checklist'!I39) -> 6.3333333 | F17: VF6NP Leading | G17: Improved design consistency and brand alignment
B18: Average | C18: =AVERAGE(C12:C17) -> 5.9444444 | D18: =AVERAGE(D12:D17) -> 5.6944444 | E18: =AVERAGE(E12:E17) -> 6.0555556 | F18: VF6NP Leading | G18: Overall competitive position achieved
B21: Interior | C21: BYD | D21: VF6 | E21: VF6NP | F21: Competitive Position | G21: Assessment
B22: Functionality | C22: =AVERAGE('PQ Audit Checklist'!G43,'PQ Audit Checklist'!G49,'PQ Audit Checklist'!G55,'PQ Audit Checklist'!G61,'PQ Audit Checklist'!G67,'PQ Audit Checklist'!G73,'PQ Audit Checklist'!G79,'PQ Audit Checklist'!G85,'PQ Audit Checklist'!G97) -> 7 | D22: =AVERAGE('PQ Audit Checklist'!H43,'PQ Audit Checklist'!H49,'PQ Audit Checklist'!H55,'PQ Audit Checklist'!H61,'PQ Audit Checklist'!H67,'PQ Audit Checklist'!H73,'PQ Audit Checklist'!H79,'PQ Audit Checklist'!H85,'PQ Audit Checklist'!H97) -> 5.3333333 | E22: =AVERAGE('PQ Audit Checklist'!I43,'PQ Audit Checklist'!I49,'PQ Audit Checklist'!I55,'PQ Audit Checklist'!I61,'PQ Audit Checklist'!I67,'PQ Audit Checklist'!I73,'PQ Audit Checklist'!I79,'PQ Audit Checklist'!I85,'PQ Audit Checklist'!I97) -> 7.3333333 | F22: VF6NP Leading | G22: Significant usability and packaging improvement
B23: Aesthetics | C23: =AVERAGE('PQ Audit Checklist'!G41,'PQ Audit Checklist'!G47,'PQ Audit Checklist'!G53,'PQ Audit Checklist'!G59,'PQ Audit Checklist'!G65,'PQ Audit Checklist'!G71,'PQ Audit Checklist'!G77,'PQ Audit Checklist'!G83,'PQ Audit Checklist'!G95) -> 7.1111111 | D23: =AVERAGE('PQ Audit Checklist'!H41,'PQ Audit Checklist'!H47,'PQ Audit Checklist'!H53,'PQ Audit Checklist'!H59,'PQ Audit Checklist'!H65,'PQ Audit Checklist'!H71,'PQ Audit Checklist'!H77,'PQ Audit Checklist'!H83,'PQ Audit Checklist'!H95) -> 6 | E23: =AVERAGE('PQ Audit Checklist'!I41,'PQ Audit Checklist'!I47,'PQ Audit Checklist'!I53,'PQ Audit Checklist'!I59,'PQ Audit Checklist'!I65,'PQ Audit Checklist'!I71,'PQ Audit Checklist'!I77,'PQ Audit Checklist'!I83,'PQ Audit Checklist'!I95) -> 7.3333333 | F23: VF6NP Leading | G23: Strong premium perception through design execution
B24: Fit & Finish | C24: =AVERAGE('PQ Audit Checklist'!G40,'PQ Audit Checklist'!G46,'PQ Audit Checklist'!G52,'PQ Audit Checklist'!G58,'PQ Audit Checklist'!G64,'PQ Audit Checklist'!G70,'PQ Audit Checklist'!G76,'PQ Audit Checklist'!G82,'PQ Audit Checklist'!G94) -> 7.1111111 | D24: =AVERAGE('PQ Audit Checklist'!H40,'PQ Audit Checklist'!H46,'PQ Audit Checklist'!H52,'PQ Audit Checklist'!H58,'PQ Audit Checklist'!H64,'PQ Audit Checklist'!H70,'PQ Audit Checklist'!H76,'PQ Audit Checklist'!H82,'PQ Audit Checklist'!H94) -> 5.7777778 | E24: =AVERAGE('PQ Audit Checklist'!I40,'PQ Audit Checklist'!I46,'PQ Audit Checklist'!I52,'PQ Audit Checklist'!I58,'PQ Audit Checklist'!I64,'PQ Audit Checklist'!I70,'PQ Audit Checklist'!I76,'PQ Audit Checklist'!I82,'PQ Audit Checklist'!I94) -> 8 | F24: VF6NP Strong Leader | G24: Best-in-class execution, major improvement vs VF6
